Workbook

Sheet How to use
A1: ARS Literature Review: Scopus screening (S1, S2, S3b)
A2: Prepared 07-10-2026 for Ethan Bastian & Ethan Croes (CS/IST pre-master, ARS, DACS4)
A4: What this file is
A5: Title/abstract screening of all 509 unique records found in Scopus, with a suggested decision and reason for each.
A6: The suggestions were made by an AI assistant (Claude) from titles and abstracts only. You must check them: you are responsible for the final decisions.
A8: How to check the screening
A9: 1. Go to the Screening sheet. Column I shows the AI suggestion, column J the reason code (see Criteria sheet).
A10: 2. If you agree, leave column N (yellow) empty. If you disagree, type your own decision in column N: Include, or an exclusion code such as EC6.
A11: 3. Column O (Final decision) updates automatically, and so do the counts on the PRISMA sheet.
A12: 4. Use the filter arrows in the header row to show e.g. only Section 2.3 or only High priority.
A14: Example: row R013 (LoRa relay for detonating explosives) is suggested as EC7. If you think it belongs in 2.1, type Include in N.
A16: Priority (column M), for included records only
... A28: Note: EC6 and EC7 were added during screening because many records were off-topic or only applications. Add them to the exclusion criteria in your review.

Sheet Search log
A1: # | B1: Date | C1: Database | D1: Purpose | E1: Search string | F1: Filters | G1: Results | H1: Note
A2: S1 | B2: 07-10-2026 | C2: Scopus | D2: Routing in LoRa mesh networks (2.1) | E2: TITLE-ABS-KEY( ("LoRa" OR "Meshtastic" OR "MeshCore") AND (mesh OR "multi-hop" OR multihop) AND (routing OR flooding OR relay*) ) AND PUBYEAR > 2013 AND PUBYEAR < 2027 | F2: None | G2: 219 | H2: Used
A3: S2 | B3: 07-10-2026 | C3: Scopus | D3: Security problems in LoRa mesh / multi-hop (2.1, 2.2) | E3: TITLE-ABS-KEY( ("LoRa" OR "LPWAN" OR "Meshtastic" OR "MeshCore") AND (mesh OR "multi-hop" OR multihop OR routing) AND (security OR confidentiality OR vulnerabilit* OR attack*) ) AND PUBYEAR > 2013 AND PUBYEAR < 2027 | F3: None | G3: 103 | H3: Used
A4: S3 | B4: 07-10-2026 | C4: Scopus | D4: Hardware limits of security on constrained devices (2.3) | E4: TITLE-ABS-KEY( ("LoRa" OR "LPWAN" OR microcontroller* OR "ESP32" OR "nRF52*" OR "RP2040") AND ("lightweight cryptography" OR "lightweight encryption" OR "embedded security" OR "resource-constrained" OR "constrained device*") AND (encryption OR authentication OR "energy consumption" OR memory) ) AND PUBYEAR > 2013 AND PUBYEAR < 2027 | F4: None | G4: 1156 | H4: Too broad: matched machine-learning "LoRA" (Low-Rank Adaptation) and TinyML papers. Refined to S3b; not screened
A5: S3b | B5: 07-10-2026 | C5: Scopus | D5: Hardware limits of security on constrained devices (2.3) | E5: TITLE-ABS-KEY( ("LoRa" OR "LPWAN" OR "ESP32" OR "nRF52*" OR "RP2040" OR "Cortex-M*") AND ("lightweight cryptography" OR "lightweight encryption" OR "embedded security" OR "resource-constrained" OR "constrained device*") AND (encrypt* OR cryptograph* OR cipher* OR authenticat*) ) AND NOT TITLE-ABS-KEY("low-rank") AND PUBYEAR > 2013 AND PUBYEAR < 2027 | F5: None | G5: 212 | H5: Used
A6: IEEE | B6: 07-10-2026 | C6: IEEE Xplore | D6: (planned) | E6: Same as S1, S2, S3b without TITLE-ABS-KEY / PUBYEAR | F6: 2014-2026 | H6: Access refused on 07-10-2026; not run. Scopus already indexes most IEEE papers.

Sheet Criteria
A1: Code | B1: Criterion | C1: Why
A2: IC1 | B2: Published 2014-2026 | C2: LoRa became available around 2014-2015
A3: IC2 | B3: Written in English | C3: Most academic output is in English (ARS3 lecture)
A4: IC3 | B4: Peer-reviewed journal/conference paper or book chapter (grey literature added separately) | C4: Quality of sources
A5: IC4 | B5: (2.1) Describes routing/forwarding in multi-hop or mesh LoRa, or its security weaknesses | C5: Sub-question 1
A6: IC5 | B6: (2.3) Implements, measures or analyses the cost of security mechanisms on LoRa-class microcontrollers | C6: Sub-question 3
A7: IC6 | B7: Full text accessible (open access or via UT library) | C7: Checked at full-text stage
A9: Code | B9: Exclusion reason | C9: Count (live)
A10: EC1 | B10: Single-hop / star LoRaWAN only, no multi-hop element | C10: =COUNTIF(Screening!$O$2:$O$510,A10) -> 5
A11: EC2 | B11: Physical layer only (modulation, coding, interference); no routing or security relevance | C11: =COUNTIF(Screening!$O$2:$O$510,A11) -> 3
A12: EC3 | B12: Hardware far above LoRa-node class (e.g. Linux servers, cloud) | C12: =COUNTIF(Screening!$O$2:$O$510,A12) -> 1
A13: EC4 | B13: Not a full paper (proceedings front matter, poster, demo, short abstract) | C13: =COUNTIF(Screening!$O$2:$O$510,A13) -> 31
A14: EC5 | B14: Duplicate or earlier version of a paper already screened | C14: =COUNTIF(Screening!$O$2:$O$510,A14) -> 3
A15: EC6 | B15: Off-topic: not about LoRa multi-hop routing/security, nor security cost on constrained hardware | C15: =COUNTIF(Screening!$O$2:$O$510,A15) -> 164
A16: EC7 | B16: Application-focused: uses LoRa (mesh) as a tool, no analysis of routing or security mechanisms | C16: =COUNTIF(Screening!$O$2:$O$510,A16) -> 51
A17: EC8 | B17: Not written in English | C17: =COUNTIF(Screening!$O$2:$O$510,A17) -> 3
A19: Category | B19: Meaning | C19: Section
A20: SURVEY | B20: Survey or review of multi-hop / mesh LoRa | C20: 2.1
A21: COMMUNITY | B21: Meshtastic, MeshCore, Pymesh or other community mesh systems | C21: 2.1
A22: PROTO | B22: Routing protocol design or evaluation for LoRa mesh | C22: 2.1
A23: FLOOD | B23: Flooding, gossip, broadcast or concurrent-transmission forwarding | C23: 2.1
A24: RELAY | B24: Relays or LoRaWAN multi-hop extensions (gateway-centred) | C24: 2.1
A25: EVAL | B25: Experimental or simulation evaluation of a LoRa mesh | C25: 2.1
A26: SEC | B26: Security weaknesses or protection in LoRa mesh / multi-hop | C26: 2.1 / 2.2
A27: FOR24 | B27: Secure-routing or trust technique (general, for 2.4) | C27: 2.4
A28: HWSURVEY | B28: Survey of security on constrained devices | C28: 2.3
A29: HWLORA | B29: Security mechanism implemented or measured on LoRa nodes | C29: 2.3
A30: HWBENCH | B30: Symmetric / lightweight crypto benchmarked on microcontrollers | C30: 2.3
A31: HWPKC | B31: Public-key, key exchange or post-quantum cost on microcontrollers | C31: 2.3

Sheet Screening
A1: ID | B1: Found by | C1: Title | D1: Year | E1: Type | F1: Authors | G1: Source | H1: DOI | I1: AI suggestion | J1: Reason code | K1: Section | L1: Category | M1: Priority | N1: Your decision (optional) | O1: Final decision | P1: Abstract
A2: R001 | B2: S1 | C2: 2017 13th Annual Conference on Wireless On-Demand Network Systems and Services, WONS 2017 - Proceedings | D2: 2017 | E2: Conference review | G2: 2017 13th Annual Conference on Wireless On-Demand Network Systems and Services, WONS 2017 - Proceedings | I2: Exclude | J2: EC4 | O2: =IF(N2="",IF(I2="Include","Include",J2),N2) -> EC4 | P2: The proceedings contain 27 papers. The topics discussed include: a dynamic and autonomous channel selection strategy for interference avoidance in 802.11; on the feasibility of collision detection in full-duplex 802.11 radio; TraceMixer: privacy-preserving crowd-sensing sans trusted third party; on the sensitivity of geo-based content sharing to location errors; the more you speak, the less you hear: on dynamic announcement intervals in wireless on-demand networks; promotion of cooperation in public goods game by socialized speed-restricted movement; offloading on the edge: performance and cost analysis of local data storage and offloading in HetNets; active energy management for harvesting enabled wireless sensor network; energy-efficient analog sensing for large scale, high-density persistent wireless monitoring; on the application of LoRa LPWAN technology in sailing monitoring system; an alternative congestion control using an enhanced contention based forwarding for vehicular networks; efficient mmwave wireless backhauling for dense small-cell deployments; dynamic RPL for multi-hop routing in IoT applications; and an SMDP approach to optimal PHY configuration in wireless networks.
A3: R002 | B3: S1 | C3: Increased flexibility in long-range IoT deployments with transparent and light-weight 2-hop LoRa approach | D3: 2019 | E3: Conference paper | F3: Diop, M.; Pham, C. | G3: IFIP Wireless Days | H3: 10.1109/wd.2019.8734228 | I3: Include | K3: 2.1 | L3: RELAY | M3: Medium | O3: =IF(N3="",IF(I3="Include","Include",J3),N3) -> Include | P3: LoRa is a recent low-power and long-range sub-GHz radio technology where devices can communicate in 1-hop to a gateway several kilometers away. Long-range radios typically remove the complexity of maintaining a multi-hop network with intermediate nodes for relaying information. Nonetheless, even with the increased range, 1-hop connectivity can be difficult to achieve in real-world deployment scenario, especially for remote and rural areas where density of gateways is low and where devices/gateway are usually deployed for a specific application. This article describes a 2-hop LoRa approach to seamlessly extend a deployed LoRa network in order to reduce both packet losses and transmission cost. We introduce a smart and battery-operated relay-device that can be added after a deployment campaign to transparently provide an extra hop between the remote devices and the gateway. Field tests are conducted to assess network reliability by dynamic insertion of a relay-device between the remote end-devices and the gateway, without advertising its presence. Energy consumption is also discussed. © 2019 IEEE.
A4: R003 | B4: S1 | C4: Distributed network communication using B.A.T.M.A.N. algorithm over LoRa | D4: 2021 | E4: Conference paper | F4: Chache, F.M.; Maxon, S.; Narayanan, R.M.; Bharadwaj, R. | G4: Proceedings of SPIE - The International Society for Optical Engineering | H4: 10.1117/12.2588317 | I4: Include | K4: 2.1 | L4: PROTO | M4: Medium | O4: =IF(N4="",IF(I4="Include","Include",J4),N4) -> Include | P4: Internet of Things (IoT) has become a fast growing research topic in recent years. Internet connected sensors and devices allow for the collection and processing of a wealth of data. This in conjunction with sensor fusion can provide greater accuracy in object recognition and detection surpassing what could be obtained by sensors operating independently. However these distributed sensors must often operate in environments with poor to no access to the internet which can greatly reduce their effectiveness. Additionally these sensors can be attached to highly dynamic platforms further complicating communication and data routing. One possible solution is to use the B.A.T.M.A.N. (Better Approach To Mobile Ad hoc Networking) routing protocol adapted for use with LoRa, a low power long range RF protocol, to route sensor data through other nodes in order to reach internet access points and allow these devices to interact with the cloud that would have otherwise been unable. Other adaptations to the algorithm will be investigated, such as including other sensors, like GPS and message signal strength to better predict route quality. This system shows promise to be an effective, fault-tolerant solution for this application. © 2021 SPIE.
A5: R004 | B5: S1 | C5: Hybrid LoRa Mesh Routing with Energy based Clustering in Heterogeneous IoT Environment | D5: 2025 | E5: Conference paper | F5: Su, A.; Abbas, F.H.; Kurdi, W.H.M.; Farhoud, H.A.; Khazaal, W.M.; Al Attabi, K. | G5: 2025 International Conference on Next Generation Computing Systems: Intelligent System for Sustainable Development, ICNGCS 2025 - Conference Proceedings | H5: 10.1109/icngcs64900.2025.11183332 | I5: Include | K5: 2.1 | L5: PROTO | M5: Low | O5: =IF(N5="",IF(I5="Include","Include",J5),N5) -> Include | P5: In recent times one of the trending technologies that are used for data collection is Internal of Things (IoT), which is applied in numerous applications of the smart devices. Due to the massive volume of data that this technology controls, smart device data- collecting procedure is quite complex, which increases delay and power consumption throughout the data- gathering process. Mainly to improve the efficiency of the smart devices and to provide effective data transmission through routing, in this article a Hybrid LoRa Mesh Routing with energy-based clustering (HLRECH) is developed. The core modules of the proposed model are the Hybrid LoRa Mesh Routing and Energy Consumption Model and the Energy-based Clustering Model. The implementation of this concept is carried out, and the software NS3 and the parameters that are involved in the analysis of the network model are routing overhead, end-to-end delay, vehicle lifetime, cluster efficiency, and the data delivery ratio. Based on the examination of the results, it is evident that HLRECH outperforms the other approaches in terms of efficiency and cluster longevity. © 2025 IEEE.
A6: R005 | B6: S1 | C6: R-AODV: Reverse Ad-Hoc On-Demand Distance Vector Routing Algorithm With LoRa Mesh Based for Emergency Alert System | D6: 2023 | E6: Conference paper | F6: Thaenthong, J.; Pimsen, T.; Chidchuea, K. | G6: 2023 15th International Conference on Information Technology and Electrical Engineering, ICITEE 2023 | H6: 10.1109/icitee59582.2023.10317648 | I6: Include | K6: 2.1 | L6: PROTO | M6: Medium | O6: =IF(N6="",IF(I6="Include","Include",J6),N6) -> Include | P6: This research introduces a LoRa mesh network for emergency notification systems, which addresses the challenges of the conventional point-to-point LoRa system, such as limited transmission range and lack of backup paths. The mesh network comprises nodes that serve as relays, facilitating multi-hop data transmission to the gateway. The network also adapts to node failures and route changes by employing the Reverse Ad-hoc On-demand Distance Vector (R-AODV) routing algorithm. The performance of the proposed system was assessed through three types of tests: point-to-point, multi-hop, and node failure. The results indicate that the LoRa mesh network improves network coverage and reliability for emergency communication. The average delay for sending alert messages from the gateway neighbor node to the gateway is 0.82s, from the alarm node to the gateway is 1.54s in normal conditions, and 11.65s in case of a gateway neighbor node failure. The user satisfaction score is 4.31 out of 5. © 2023 IEEE.
A7: R006 | B7: S1 | C7: A Multi-Hop Routing Solution for Low Latency and Energy Efficiency in Large-Scale LoRa IoT | D7: 2025 | E7: Journal article | F7: Misbahuddin, M.; Iqbal, M.S.; Akbar, L.A.S.I. | G7: International Journal of Computers, Communications and Control | H7: 10.15837/ijccc.2025.3.6501 | I7: Include | K7: 2.1 | L7: PROTO | M7: Medium | O7: =IF(N7="",IF(I7="Include","Include",J7),N7) -> Include | P7: This paper presents a novel multi-hop routing approach for large-scale LoRa IoT networks that aims to solve the challenges of low latency and energy efficiency. The proposed protocol seeks to minimize energy usage and enable wirelessly data transfer by utilizing the unique features of LoRa communication technology. To ensure reliable communication in a multi-hop context, the protocol includes a dynamic routing mechanism that optimizes network latency and prevents data packet collisions. Furthermore, scalability is another important consideration since it permits the flexible addition of new nodes. The simulation results show that the proposed approach is effective, which shows improved energy savings, less latency, and strong flexibility. These results offer a promising solution for optimizing the performance of large-scale LoRa IoT deployments. © (2025), (Agora University). All rights reserved.
A8: R007 | B8: S1 | C8: QoS Extension to a B.A.T.M.A.N. based LoRa Mesh Network | D8: 2021 | E8: Conference paper | F8: Chache, F.M.; Maxon, S.; Narayanan, R.M.; Bharadwaj, R. | G8: Proceedings - IEEE Military Communications Conference MILCOM | H8: 10.1109/milcom52596.2021.9653022 | I8: Include | K8: 2.1 | L8: PROTO | M8: Low | O8: =IF(N8="",IF(I8="Include","Include",J8),N8) -> Include | P8: To be useful, wireless sensor networks (WSNs) must be relied upon even when dispersed across environments that lack consistent internet access. To this end, we propose a mesh network architecture based on the Better Approach to Mobile Ad-hoc Networking (B.A.T.M.A.N.) algorithm in conjunction with the long range, low power communication protocol, LoRa, to transmit messages. Adaptations including methods of time synchronization, slotted ALOHA transmission and Quality of Service (QoS) considerations with a network-traffic-aware data routing protocol for a multi-source/multi-sink network configuration have been implemented. With this solution, nodes can create an ad-hoc network, sharing internet access and greatly expanding the network coverage without the need for any additional infrastructure. Our QoS-aware routing metrics have been tested in simulation and show performance improvements over traditional B.A.T.M.A.N. destination routing algorithms in these low data rate systems. © 2021 IEEE.
A9: R008 | B9: S1 | C9: Development of a Mathematical Model for Estimating the Energy Efficiency and Throughput of a Decentralized LoRa Network with Account for Dynamically Changing Signal Propagation Conditions | D9: 2026 | E9: Conference paper | F9: Tsoy, D.C.; Kazadaev, L.M.; Lipatkin, V.I.; Ryumshin, K.Y. | G9: 2026 Systems of Signals Generating and Processing in the Field of on Board Communications, SOSG 2026 - Conference Proceedings | H9: 10.1109/ieeeconf68869.2026.11460393 | I9: Include | K9: 2.1 | L9: PROTO | M9: Medium | O9: =IF(N9="",IF(I9="Include","Include",J9),N9) -> Include | P9: This article addresses the problem of evaluating energy efficiency and data throughput in decentralized LoRa mesh networks under dynamically changing propagation conditions. In contrast to centralized LoRaWAN architectures, where devices communicate exclusively through gateways, the mesh topology considered here enables multi-hop data delivery via intermediate nodes. This is especially relevant in conditions of urban dense development, where direct node-to-gateway links are often disrupted by obstacles or excessive distance. A simulation model of the physical layer (PHY) of LoRa is developed in MATLAB, incorporating an AWGN channel and a frequency-selective Rayleigh TDL channel calibrated according to ITU-R P.1411-10 recommendations. The packet error rate (PER) and bit error rate (BER) are used as the primary quality metrics, while network throughput and end-to-end reliability are evaluated as functions of the number of relay hops. The effect of the LoRa coding rate (CR = 4/5 versus CR = 4/8) on the residual error floor and end-to-end performance is investigated as a means of mitigating irreducible fading losses. ©2026 IEEE.
A10: R009 | B10: S1 | C10: A GNN-Based Learning Approach for Energy Optimization in Relay-Assisted IoT Networks | D10: 2025 | E10: Conference paper | F10: Yang, H.; Ji, H.; Huang, Z.; Wu, X. | G10: IEEE Wireless Communications and Networking Conference, WCNC | H10: 10.1109/wcnc61545.2025.10978775 | I10: Include | K10: 2.1 | L10: RELAY | M10: Low | O10: =IF(N10="",IF(I10="Include","Include",J10),N10) -> Include | P10: Minimizing energy consumption is critical for the long-range (LoRa) Internet of Things (IoT) networks, to extend the battery lifetime of end devices (EDs) while reducing the maintenance cost. To overcome the excessive computational complexity required by the traditional optimization methods, learning approaches such as deep neural network (DNN) and reinforcement learning (RL) have been researched in wireless networks, where star topologies are widely employed. In contrast, LoRa usually deploys relays to assist the connection between the EDs and the gateway (GW), leading to a much more complex network topology. Consequently, DNN and RL would become less effective in LoRa, since those methods are difficult to learn the complex network topology constructed by LoRa. In this paper, we propose a learning method based on graph neural network (GNN), which is known for its prominent ability to capture and represent intricate graph-structural dependencies, to tackle the energy optimization problem for relay-assisted LoRa. Specifically, the multi-hop LoRa network is modeled as a directed graph, with channel state information (CSI) defined as node features, while the spreading factor and transmission power are deemed labels. A hierarchical message aggregation mechanism is proposed to effectively capture the multi-hop structural dependencies, followed by the process of inductive learning. Results show that against conventional optimization algorithms, the proposed method can achieve near-optimal energy consumption with a gap of 10% to 16%, while reducing the runtime by about six orders of magnitude. Compared to DNN, the GNN-based model can provide an energy saving of up to 32%, at a similar level of inference time. © 2025 IEEE.
A11: R010 | B11: S1 | C11: A Comparative Evaluation of LoRa Mesh, Peer-to-Peer and Satellite Communication Systems for Lunar IoT Applications | D11: 2026 | E11: Conference paper | F11: Impraim, N.N.; Bayrak, S. | G11: RAST 2026 - 11th International Conference on Recent Advances in Air and Space Technologies, Conference Program | H11: 10.1109/rast69551.2026.11672553 | I11: Include | K11: 2.1 | L11: EVAL | M11: Low | O11: =IF(N11="",IF(I11="Include","Include",J11),N11) -> Include | P11: This paper presents a performance comparison of three LoRa-based communication systems. Mesh Networks, Point-to-Point (P2P), and satellite gateways for Lunar-IoT networks. In this study, an evaluation framework has been developed that reflects the lunar environment. This includes factors like radiation-induced bit errors, extreme temperature changes (+130°C to -170°C), 14-day day/night cycles, terrain-related path loss from craters and regolith, and vacuum propagation. In testing 25 distributed nodes over a 5 km coverage area, the mesh network achieved a packet delivery rate (PDR) of 97.06%. In contrast, the P2P architecture had a PDR of 23.60%, while the satellite system achieved 74.15%. P2P had the lowest latency at (319 ms), and the least energy use, but single-hop limits resulted in 76% of transmissions failing in low-density lunar deployments. Satellite communication ensured reliable connections but came with much higher latency (2079 ms) and energy usage. Networks using multi-hop routing with a 1.5 km distance between nodes created the best balance of reliability and efficiency for lunar operations. This study provides performance comparisons essential for planning a LoRa-based communication system on the Moon. © 2026 IEEE.
A12: R011 | B12: S1 | C12: Analytic Model of a Mesh Topology based on LoRa Technology | D12: 2020 | E12: Conference paper | F12: Kirichek, R.; Vishnevsky, V.; Pham, V.D.; Koucheryavy, A. | G12: International Conference on Advanced Communication Technology, ICACT | H12: 10.23919/icact48636.2020.9061519 | I12: Include | K12: 2.1 | L12: PROTO | M12: Medium | O12: =IF(N12="",IF(I12="Include","Include",J12),N12) -> Include | P12: In the last decade, the Internet of Things (IoT) technologies have brought a lot of applications in different fields. Many communication technologies have been developed in order to connect everything to each other and to the Internet. Besides, the long-range power-efficient wireless technologies have emerged such as LoRa (Long Range), which enables transmission over long distances with low energy consumption and can work within p2p, star or mesh topologies. In this paper, we analyze a model of a mesh topology for the LoRa network, which is attracting more interest in the applications of Smart City and Smart Agriculture. While the mesh topology is described by a graph, a method of route selection is considered based on the link quality related to Received Signal Strength Indication (RSSI) to find the optimal path from a source to a sink node. The network performance is evaluated by considering each node as a queueing system. As the analytic results, the routes are found from device nodes to the gateway, and the delivery latency is analyzed in the dependence on the load intensity and the number of relay nodes. © 2020 Global IT Research Institute - GIRI.
A13: R012 | B13: S1 | C13: Design Considerations and Performance Evaluation of Gossip Routing in LoRa-Based Linear Networks | D13: 2023 | E13: Journal article | F13: Liaqat, R.M.; Branch, P.; But, J. | G13: Future Internet | H13: 10.3390/fi15110366 | I13: Include | K13: 2.1 | L13: FLOOD | M13: High | O13: =IF(N13="",IF(I13="Include","Include",J13),N13) -> Include | P13: Linear networks (sometimes called chain-type networks) occur frequently in Internet of Things (IoT) applications, where sensors or actuators are deployed along pipelines, roads, railways, mines, and international borders. LoRa, short for Long Range, is an increasingly important technology for the IoT with great potential for linear networking. Despite its potential, limited research has explored LoRa’s implementation in such networks. In this paper, we addressed two important issues related to LoRa linear networks. The first is contention, when multiple nodes attempt to access a shared channel. Although originally designed to deal with interference, LoRa’s technique of synchronisation with a transmission node permits a novel approach to contention, which we explored. The second issue revolves around routing, where linear networks permit simpler strategies, in contrast to the common routing complexities of mesh networks. We present gossip routing as a very lightweight approach to routing. All our evaluations were carried out using real equipment by developing real networks. We constructed networks of up to three hops in length and up to three nodes in width. We carried out experiments looking at contention and routing. We demonstrate using the novel approach that we could achieve up to 98% throughput. We compared its performance considering collocated scenarios that achieved 84% and 89% throughputby using relay widths of two and three at each hop, respectively. Lastly, we demonstrate the effectiveness of gossip routing by using various transmission probabilities. We noticed high performance up to 98% throughputat (Formula presented.) = 0.90 and (Formula presented.) = 0.80 by employing two and three active relay nodes, respectively. The experimental result showed that, at (Formula presented.) = 0.40, it achieved an average performance of 62.8% and 73.77% by using two and three active relay nodes, respectively. We concluded that LoRa is an excellent technology for Internet of Things applications where sensors and actuators are deployed in an approximately linear fashion. © 2023 by the authors.
A14: R013 | B14: S1 | C14: A LoRa relay based system for detonating explosives in underground mines | D14: 2020 | E14: Conference paper | F14: Branch, P.; Cricenti, T. | G14: Proceedings of the IEEE International Conference on Industrial Technology | H14: 10.1109/icit45562.2020.9067213 | I14: Exclude | J14: EC7 | O14: =IF(N14="",IF(I14="Include","Include",J14),N14) -> EC7 | P14: In this paper we present our work on the use of LoRa as a network technology for detonation of low explosives in underground mining. Using explosives underground is a potentially hazardous activity that mining companies are keen to make safer by removing personnel from near the site of the detonation. Currently detonation is commonly carried out using lengths of copper cable or infrared transmission, both of which limit the distance between the initiator and the explosives. The wireless technology LoRa, is an attractive alternative. LoRa has a much longer transmission range than infrared transmission and other wireless technologies such as WiFi and ZigBee. We have developed and trialed in a working underground mine a prototype system for carrying out such detonations. The system makes use of LoRa as a multi-hop message passing system from an Initiator to a Detonator via a number of Relays. We describe the messages that are passed through the network. We also describe how we deal with contention, broadcast storms and duplicate messages. Our approach is robust, easy to deploy and gives deterministic delay. We also present measurements of signal strength taken underground. Our results indicate that underground LoRa wireless transmission suffers severe fading without line of sight but where this is a line of sight underground, we show that LoRa propagates considerable distances. © 2020 IEEE.
A15: R014 | B15: S1, S2 | C15: MSWiM 2021 - Proceedings of the 24th International ACM Conference on Modeling, Analysis and Simulation of Wireless and Mobile Systems | D15: 2021 | E15: Conference review | G15: MSWiM 2021 - Proceedings of the 24th International ACM Conference on Modeling, Analysis and Simulation of Wireless and Mobile Systems | I15: Exclude | J15: EC4 | O15: =IF(N15="",IF(I15="Include","Include",J15),N15) -> EC4 | P15: The proceedings contain 29 papers. The topics discussed include: preventing failures of cooperative maneuvers among connected and automated vehicles; global energy optimization strategy based on delay constraints in edge computing environment; profit maximization for service placement and request assignment in edge computing via deep reinforcement learning; accelerating the simulation of wireless communication protocols using asynchronous parallelism; modeling and simulation of reconfigurable intelligent surfaces for hybrid aerial and ground-based vehicular communications; an energy-efficient smart space system using lora network with deadline and security constraints; a novel harvesting-aware RL-based opportunistic routing protocol for underwater sensor networks; and simple and efficient collision-free channel access in multi-hop wireless networks.
A16: R015 | B16: S1 | C16: Energy-Efficient Multi-Hop LoRa Communication in Forested Environments via Proximal Policy Optimization | D16: 2026 | E16: Journal article | F16: Jumali, M.K.B.; Guan, L.K.; Moung, E.G.; Angeline, L.; Wang, T.; Kin, K.T.T. | G16: International Journal of Advanced Computer Science and Applications | H16: 10.14569/ijacsa.2026.0170436 | I16: Include | K16: 2.1 | L16: PROTO | M16: Low | O16: =IF(N16="",IF(I16="Include","Include",J16),N16) -> Include | P16: Multi-hop LoRa networks extend coverage for large-scale Internet of Things deployments but are severely limited by interference-induced collisions, retransmissions, and rapid battery depletion of relay nodes. Conventional routing strategies that minimize hop count or rely on static heuristics fail to account for dynamic medium contention and its impact on energy consumption and reliability. This paper proposes a Proximal Policy Optimization (PPO)-based routing framework for multi-hop LoRa networks that learns interference-aware and energy-efficient routing policies through reinforcement learning. A discrete-event simulation framework is developed to model LoRa physical-layer behaviour, co-spreading-factor interference, adaptive data rate control, and battery-limited relay nodes under multi-source traffic. The routing problem is formulated as a Markov Decision Process (MDP) in which the PPO agent selects next-hop relays based on local topology, relay load, and channel occupancy, while physical-layer parameters are adapted independently using a standards-inspired physical-layer parameters are adapted independently using a standards-inspired ADR mechanism (ADR) mechanism. Simulation results show that the proposed approach achieves a packet delivery ratio of up to 73.7%, reduces collision rates by approximately 46% compared with Random routing, and lowers the average energy consumption per delivered packet to about 206 mJ, outperforming Shortest Path and Ad hoc On-Demand Distance Vector (AODV)-like routing. These gains are achieved by learning spatially diverse routing paths that mitigate relay congestion and reduce collision-induced retransmissions. © 2026, The Author(s).
A17: R016 | B17: S1 | C17: Simulated Disaster Warning System for Remote Areas using Multi-Hop LEACH over LoRa Mesh Network | D17: 2026 | E17: Conference paper | F17: Pradeep Kumar, G.; Afeef Ahmed Kamal, A.; Bala Ramanan, B.; Imthiyaz Ahamed, A.; Siddharth, M. | G17: 4th International Conference on Integrated Circuits and Communication Systems, ICICACS 2026 | H17: 10.1109/icicacs68679.2026.11578885 | I17: Include | K17: 2.1 | L17: PROTO | M17: Low | O17: =IF(N17="",IF(I17="Include","Include",J17),N17) -> Include | P17: This research addresses the critical failure of conventional communication infrastructures during climatic disasters, particularly in geographically isolated regions where "last mile"connectivity is often the first to fail. Conventional systems like GSM and standard LoRaWAN suffer from single points of failure and congestion. To overcome these limitations, we propose a robust, autonomously survivable architecture synthesizing Multi-Hop Low energy Adaptive Clustering Hierarchy (LEACH) protocols with the Long Range (LoRa) physical layer. The proposed method introduces a decentralized mesh topology controlled by a novel "Node Rank"(NR) algorithmic fitness function, which deterministically assigns Cluster Heads based on residual energy, proximity to the sink, and connectivity degree. Extensive stochastic modeling and discrete-event simulations in Network Simulator 2 (NS2) demonstrate that this approach achieves a 96% Packet Delivery Ratio (PDR), reduces end-to-end latency to 1.9s, and extends network lifetime by 80% compared to AODV and single-hop paradigms. These results confirm the system's viability as a resilient backbone for next-generation disaster informatics, ensuring reliable early warnings even when traditional networks collapse. © 2026 IEEE.
A18: R017 | B18: S1 | C18: Cross-network cross-interface relaying via LoRa-ZigBee synergy: Enabling energy-efficient delay-constrained communication across low-power IoT networks | D18: 2026 | E18: Journal article | F18: Qin, H.; Li, N.; Yang, G.; Peng, Y. | G18: Internet of Things (The Netherlands) | H18: 10.1016/j.iot.2026.101878 | I18: Exclude | J18: EC6 | O18: =IF(N18="",IF(I18="Include","Include",J18),N18) -> EC6 | P18: The rapid expansion of the Internet of Things (IoT) ecosystem has propelled widespread deployment of distributed low-power wireless networks, among which ZigBee stands out for diverse innovative applications. However, energy-efficient cross-network communication remains challenging, as existing solutions like multi-hop ZigBee and one-hop LoRa entail trade-offs between communication delays and deployment costs. To tackle these issues, we propose a novel cross-interface relaying paradigm that utilizes a star topology within each ZigBee network and designates a relay node with an additional LoRa interface to bridge networks via a central LoRa gateway. Compared with existing methods, this approach reduces energy consumption and costs while improving scalability. To implement this paradigm while balancing energy conservation with delay guarantees, we introduce a Cross-network Cross-interface Relaying (CCR) scheme, which jointly schedules LoRa and ZigBee transmission behaviors to minimize energy consumption under delay constraints. CCR uses a scheduling framework that breaks down end-to-end delay constraints into link-level constraints, enabling global optimization of transmission parameters and dynamic adaptation to link quality variations. The effectiveness of CCR is demonstrated through extensive field tests on a prototype implemented on Raspberry Pi 3B+. Results show that CCR reduces energy consumption by 55.4% and 39.1% compared with an advanced LoRa communication protocol and a state-of-the-art cross-interface relaying scheme, respectively, while ensuring that 98.7% of packets satisfy their delay constraints. These findings highlight the potential of CCR for efficient and reliable cross-network communication in large-scale IoT deployments. © 2026 Elsevier B.V.
A19: R018 | B19: S1 | C19: Large and reliable data transfer service for LoRa mesh network applications | D19: 2026 | E19: Journal article | F19: Miquel Solé, J.; Pueyo Centelles, R.; Freitag, F.; Meseguer, R.; Baig Viñas, R. | G19: Computer Communications | H19: 10.1016/j.comcom.2025.108404 | I19: Include | K19: 2.1 | L19: PROTO | M19: Medium | O19: =IF(N19="",IF(I19="Include","Include",J19),N19) -> Include | P19: Recently, LoRa mesh networks have appeared as a communication technology for Internet of Things (IoT) devices. Through node-to-node communication, novel distributed IoT applications that extend beyond the capabilities of the LoRaWAN architecture can be enabled. However, current technologies for LoRa networks do not provide mechanisms for large and reliable data transfers between IoT nodes. This paper presents a service for such data transfers in LoRa mesh network applications, along with the protocol and formats used for inter-node communication. We explain the design choices and detail the implementation decisions to ensure that this service is practically usable. To this end, the service was integrated into the LoRaMesher library and is available as an open-source operational implementation. In experiments with ten real nodes and two network topologies, we observe that the service effectively achieves a large and reliable message delivery in an environment of concurrent transmissions and packet losses. In contrast, the cost of reliability for large data transfers is an increased number of messages and a higher delivery time. With the integration of the service into the LoRaMesher technology, developers now have a library that provides a reliable and large payload service for LoRa mesh network applications, eliminating the need to develop such capacity as a specific application-level solution. © 2025
A20: R019 | B20: S1 | C20: Experimental LoRa Network Power Consumption Model Using Multi-Hops | D20: 2022 | E20: Conference paper | F20: Alexander, U.; Bolshakov, I.; Voskov, L.; Rolich, A. | G20: Moscow Workshop on Electronic and Networking Technologies, MWENT 2022 - Proceedings | H20: 10.1109/mwent55238.2022.9802378 | I20: Include | K20: 2.1 | L20: RELAY | M20: Low | O20: =IF(N20="",IF(I20="Include","Include",J20),N20) -> Include | P20: The article describes the study of data transmission methods in heterogeneous networks using LoRa relay and NB-IoT gateway for use in an underdeveloped or absent Internet network infrastructure. The analysis of the subject area is carried out, a multistage architecture of a heterogeneous network of the Internet of Things is proposed, using repeaters and a gateway to collect remote data. A method and a calculation model of energy consumption for the transmission of collected data using repeaters is proposed, which makes it possible to increase the energy efficiency of data transmission from end devices using autonomous powersources. A prototype of a data acquisition system withretransmission has been developed, which confirms the theoretical calculations. The practical value lies in increasing thebattery life and expanding the network coverage area. © 2022 IEEE.
A21: R020 | B21: S1 | C21: Reducing Routing Overhead with a Clustering Protocol Based on Ad hoc Distance Vector and Dynamic Source Routing Protocols | D21: 2022 | E21: Conference paper | F21: Kebeng, T.O.; Sheikh, S.M.; Kgwadi, M. | G21: 5th International Conference on Artificial Intelligence, Big Data, Computing and Data Communication Systems, icABCD 2022 - Proceedings | H21: 10.1109/icabcd54961.2022.9856116 | I21: Include | K21: 2.1 | L21: PROTO | M21: Low | O21: =IF(N21="",IF(I21="Include","Include",J21),N21) -> Include | P21: Some wireless network applications only need to send data infrequently and at low bit rates. To save costs, these networks use modest devices with limited resources (bandwidth, power) or legacy technology. Technologies such as Bluetooth Low Energy, Lora Wide Area Networks (LoRAWAN), Zigbee, legacy WIFI among others, are suited for such applications. Since bandwidth is a limited resource for such networks, route discovery needs to use as little as possible, leaving most of the bandwidth available for data transfer. In this paper, the routing protocol for use in wireless, multihop ad-hoc networks, the Ad-Hoc Distance Vector (AODV) routing protocol is compared to a novel routing protocol called Cluster Based AODV (CLUBAA). The comparison is made using simulations, and the results show CLUBAA to have better bandwidth utilization due to its low Normalized Routing Overhead (NRO) for infrequent route discovery requests. The results further expand on the region of the curve where CLUBAA outperformed AODV, showing that there is a niche area where CLUBAA could be a good bandwidth saving alternative to AODV. © 2022 IEEE.
A22: R021 | B22: S1 | C22: 23rd International Conference on Distributed Computer and Communication Networks, DCCN 2020 | D22: 2020 | E22: Journal article | G22: Lecture Notes in Computer Science (including subseries Lecture Notes in Artificial Intelligence and Lecture Notes in Bioinformatics) | I22: Exclude | J22: EC4 | O22: =IF(N22="",IF(I22="Include","Include",J22),N22) -> EC4 | P22: The proceedings contain 55 papers. The special focus in this conference is on Distributed Computer and Communication Networks. The topics include: Architectural ML Framework for IoT Services Delivery Based on Microservices; applying Machine Learning to Data from a Structured Database in a Research Institute to Support Decision Making; generation of Metadata for Network Control; IoT Traffic Prediction with Neural Networks Learning Based on SDN Infrastructure; Transmission Latency Analysis in Cloud-RAN; Resource Queuing System with Preemptive Priority for Performance Analysis of 5G NR Systems; redundant Servicing of a Flow of Heterogeneous Requests Critical to the Total Waiting Time During the Multi-path Passage of a Sequence of Info-Communication Nodes; preface; Power Domain NOMA Without SIC in Downlink CSS-Based LoRa Networks; agriculture Management Based on LoRa Edge Computing System; dynamic Algorithm for Building Future Networks Based on Intelligent Core Network; Methods and Models for Using Heterogeneous Gateways in the Mesh LPWANs; Research on Using the AODV Protocol for a LoRa Mesh Network; on the Algebraic Theory of Loop Free Routing; queueing System with Two Unreliable Servers and Backup Server as a Model of Hybrid Communication System; flexible Random Early Detection Algorithm for Queue Management in Routers; architecture and Functionality of the Collective Operations Subnet of the Angara Interconnect; The Model of WBAN Data Acquisition Network Based on UFP; Development and Investigation of Model Network IMT2020 with the Use of MEC and Voice Assistant Technologies; Simulation-Based Analysis of Mobility Models for Wireless UAV-to-X Networks; queues with Markovian Arrivals, Phase Type Services, Breakdowns, and Repairs.
A23: R022 | B23: S1 | C23: IEEE Region 10 Annual International Conference, Proceedings/TENCON | D23: 2018 | E23: Conference review | G23: IEEE Region 10 Annual International Conference, Proceedings/TENCON | I23: Exclude | J23: EC4 | O23: =IF(N23="",IF(I23="Include","Include",J23),N23) -> EC4 | P23: The proceedings contain 489 papers. The topics discussed include: design of IoT monitoring system based on LoRa technology for starfruit plantation; automatic optic disc localization using particle swarm optimization technique; performance evaluation of Gbps X-band satellite downlink with transmitter imperfections; describing methods for high-level synthesis of histogram generation and their evaluation; a novel fault-tolerant routing technique for mesh-of-tree based network-on-chip design; gyroscopic stabilizer for 3D mapping device on unmanned ground vehicle; feeder wise net metering service planning using load power demand profile and raw customer billing data; non-uniform quantization based reporting in cooperative cognitive radio; pixel-level crack detection using U-Net; and interference limit based resource allocation for low density signature OFDM in underlay cognitive radio networks.
A24: R023 | B24: S1 | C24: The MauMe network - A LoRa multi-hop collaborative protocol and low-cost implementation example | D24: 2023 | E24: Journal article | F24: Mari, J.-M.; Gabillon, A. | G24: Computer Standards and Interfaces | H24: 10.1016/j.csi.2023.103733 | I24: Include | K24: 2.1 | L24: PROTO | M24: Medium | O24: =IF(N24="",IF(I24="Include","Include",J24),N24) -> Include | P24: Low-cost low-power long-distance LoRa radio devices recently made available on the market allow the emerging of a new generation of networking paradigms on the Internet of Things. While the LoRaWan offers an efficient way of connecting LoRa end-point devices to the internet, LoRaWan nodes do not act as peers, but rather as terminals connected to gateways. As such, the current state of the art does not offer a public protocol for easily taking advantage of the fact that individuals and professionals wishing to aggregate data using LoRa devices are likely to run each a “base-node” on a continuous basis. Such permanently-powered base-nodes could potentially offer an increased cumulated area coverage to other nodes if they would behave as relays. In the present study, an Epidemic Delay Tolerant Network messaging protocol is proposed, which allows multi-hops between peer LoRa relay-nodes through a raw-LoRa controlled-flooding approach. This protocol has been implemented on low-cost LoRa-chip-equipped microcontrollers in the form of an open-source library acting as a network transport-layer. The design analysis concluded that MauMe is better suited for networks with reduced connectivity (≤ 9), and that a 4-connectivity redundant network could allow each user to send several tens of messages several tens of hops away. The proposed approach was tested on three different LoRa network topologies, and the totality of the packets and acknowledgments reached their destination. Furthermore, the network's activity ceased after delivery, confirming the ability of the protocol to return the network to rest after the flooding. The proposed library also offers to users a free emergency-messaging system implemented as an http server embedded in each node and accessible via Wi-fi. End-users can readily use our solution to easily deploy a network of sensors at a much lower cost than when using multiple gateways. The MauMe protocol is a first step towards the creation of collaborative and application-friendly extended-range LoRa-peers networks, and is intended for use in remote regions with scattered housings such as in the islands and atolls of Polynesia. © 2023 Elsevier B.V.
A25: R024 | B25: S1 | C25: Research on Using the AODV Protocol for a LoRa Mesh Network | D25: 2020 | E25: Conference paper | F25: Pham, V.D.; Le, D.T.; Kirichek, R.; Shestakov, A. | G25: Lecture Notes in Computer Science (including subseries Lecture Notes in Artificial Intelligence and Lecture Notes in Bioinformatics) | H25: 10.1007/978-3-030-66471-8_13 | I25: Include | K25: 2.1 | L25: PROTO | M25: Medium | O25: =IF(N25="",IF(I25="Include","Include",J25),N25) -> Include | P25: In this paper, we consider the LoRa technology to expand sensor network coverage in smart sustainable cities. A model of a LoRa mesh network is proposed using the AODV protocol in packet routing. With a simulation model developed based on OMNET++, a series of computer experiments was carried out with changing various parameters. In the experiments results, the end-to-end delay and packet loss ratio were analyzed in the dependence on the number of nodes and packet size in the network. The simulation results show that the latency is relatively high in the LoRa mesh network, but it might be accepted for some applications. © 2020, Springer Nature Switzerland AG.
A26: R025 | B26: S1 | C26: Simple Protocol Design of Multi-Hop Network in Lora | D26: 2019 | E26: Conference paper | F26: Azhari, R.Y.; Firmansyah, E.; Bejo, A. | G26: 2019 2nd International Seminar on Research of Information Technology and Intelligent Systems, ISRITI 2019 | H26: 10.1109/isriti48646.2019.9034662 | I26: Include | K26: 2.1 | L26: PROTO | M26: Low | O26: =IF(N26="",IF(I26="Include","Include",J26),N26) -> Include | P26: Long Range (LORA) is a device capable of communicating remotely with LPWAN topologies. LPWAN cannot do multi-hop so this research needed to be done. There are several multi-hop supporting algorithms such as Media Access Control (MAC) and routing table. This paper discusses a simple routing table algorithm and messages delivered with the requirement that the next node is bigger or smaller than what is sent. Node tables and proposed method in single multi-hop produced 99% PDR. © 2019 IEEE.
A27: R026 | B27: S1, S2 | C27: Exploring open source and proprietary LoRa mesh technologies | D27: 2024 | E27: Journal article | F27: Hammouti, M.; Moussaoui, O.; Hassine, M.; Betari, A. | G27: Indonesian Journal of Electrical Engineering and Computer Science | H27: 10.11591/ijeecs.v34.i2.pp960-969 | I27: Include | K27: 2.1 | L27: SURVEY | M27: High | O27: =IF(N27="",IF(I27="Include","Include",J27),N27) -> Include | P27: This paper explores low power wide area network (LPWAN) LoRa and its diverse variants, encompassing open-source and proprietary wireless mesh networks, operating over the physical LoRa or LoRaWAN layer. The primary challenge lies in defining an optimal LoRa mesh solution that balances cost-effectiveness, energy efficiency, low latency, long-range capability, and security. This study also comprehensively examines key LoRa mesh solutions from 2017 to 2024, as proposed by various authors. Furthermore, a detailed analysis is conducted to contrast open-source and commercial solutions, considering their applications, limitations, issues, characteristics, and pros and cons of mesh routing protocols. In the current landscape, the proliferation of open-source and proprietary LoRa mesh solutions has been instrumental in facilitating the connectivity of internet of things (IoT) devices. However, these solutions pose challenges related to energy consumption, latency, and suboptimal transmission throughput. These challenges are influenced by various LoRa characteristics such as spectrum factor, bandwidth, and transmission power, which directly impact the transmission range. Our research aims to perform a comparative analysis of existing LoRa mesh solutions by, systematically studying their advantages and disadvantages. This analysis offers valuable insights for making informed choices among these solutions in diverse domains for IoT applications. © 2024 Institute of Advanced Engineering and Science. All rights reserved.
A28: R027 | B28: S1 | C28: Multi-Protocol Wireless Mesh Sensor Network | D28: 2024 | E28: Conference paper | F28: Wei, W.J.; Sheng Jovian, L.H.; Choon How, B.L.; Richie, W.R.; Yuan, P.X.; Abhishek, N.V.; Bin Abbas, M.F. | G28: 2024 IEEE VTS Asia Pacific Wireless Communications Symposium, APWCS 2024 | H28: 10.1109/apwcs61586.2024.10679304 | I28: Include | K28: 2.1 | L28: EVAL | M28: Low | O28: =IF(N28="",IF(I28="Include","Include",J28),N28) -> Include | P28: Wireless Sensor Networks (WSNs) are pivotal for real-time environmental monitoring applications. This paper delves into the detailed architecture and performance analysis of two prominent protocols, ESP-NOW and LoRa, within the context of a WSN setup. The ESP-NOW protocol, utilizing a Dynamic Source Routing (DSR) mesh algorithm, excels in throughput, latency, and bandwidth compared to LoRa, making it suitable for high-speed, low-latency communication needs. Conversely, LoRa demonstrates advantages in long-range communication and obstacle penetration. Additionally, the analysis delves into power consumption, where ESP-NOW outshines LoRa in both idle and active network states. This results demonstrated that the energy efficiency of ESP-NOW is particularly advantageous for battery-operated devices and remote deployments. The findings presented also provided valuable insights for optimizing protocol selection and power management strategies in WSN deployments, ensuring efficient and reliable data transmission in diverse environmental monitoring scenarios. © 2024 IEEE.
A29: R028 | B29: S1, S2 | C29: LDPC Over Multihop LoRa Nodes with Peeling Decoder | D29: 2023 | E29: Conference paper | F29: Arifianto, M.S. | G29: Proceeding of 2023 9th International Conference on Wireless and Telematics, ICWT 2023 | H29: 10.1109/icwt58823.2023.10335410 | I29: Exclude | J29: EC2 | O29: =IF(N29="",IF(I29="Include","Include",J29),N29) -> EC2 | P29: Wireless radio communication is expected to reach long distances and be of good quality. To achieve long-distance radio communication, relay stations can be added between the source to the destination points as needed. The utilization of wireless radio introduces vulnerabilities to the quality of communication due to noise and interference. In this research a multihop communications is created using four stationary LoRa nodes. Error correction and detection were added to the multihop communication. The Low-Density Parity Check (LDPC) regular binary 16x32 technique is used in this research for multihop communication at encoder node 1 and decoder node 4. Meanwhile, node 2 and node 3 serve as repeaters between node 1 and node 4. The type of LDPC used is binary encoder, and the decoder uses the peeling technique. Each node's implementation involves the use of hardware modules BeagleBone Black Industrial and LoRa Ebyte. The software utilized includes the debian console and Python programming. This multihop communication has undergone testing for parameters such as processing time, RSSI field test, and peeling error detection and correction ability. © 2023 IEEE.
A30: R029 | B30: S1 | C30: Cost Effective Routing in Large-scale Multi-hop LoRa Networks | D30: 2022 | E30: Conference paper | F30: Feng, S.; Chen, J.; Zhao, Z. | G30: INFOCOM WKSHPS 2022 - IEEE Conference on Computer Communications Workshops | H30: 10.1109/infocomwkshps54753.2022.9798302 | I30: Include | K30: 2.1 | L30: PROTO | M30: Medium | O30: =IF(N30="",IF(I30="Include","Include",J30),N30) -> Include | P30: Low-Power Wide-Area Network (LPWAN) technologies promoted the communication capacities of Internet of Things (IoT) to several or even dozens of kilometers. LoRa is one of these technologies characterized with longrange, low data rates and low power consumption. The LoRaWAN architecture is applied to a star-of-stars topology. However, in several non-line-of-sight or larger scale deployment scenarios, such as underground deployment and large-scale military launch, the single-hop topology may not meet the requirements. Adding gateways to increase coverage may increase deployment complexity and reduce information sharing. Furthermore, the exhaustion of a single node in the network will bring extra cost of replacing the battery, further reducing the network lifetime. Consequently, this paper introduces a multi-hop protocol MLoRa to solve these problems. MLoRa gives a routing strategy upon network layer, which not only brings cost-effective coverage but also lower and balanced energy consumption for the same coverage in LoRa networks. © 2022 IEEE.
A31: R030 | B31: S1, S2 | C31: 17th International Conference on Ad Hoc Networks and Wireless, ADHOC-NOW 2018 | D31: 2018 | E31: Journal article | G31: Lecture Notes in Computer Science (including subseries Lecture Notes in Artificial Intelligence and Lecture Notes in Bioinformatics) | I31: Exclude | J31: EC4 | O31: =IF(N31="",IF(I31="Include","Include",J31),N31) -> EC4 | P31: The proceedings contain 29 papers. The special focus in this conference is on Ad Hoc Networks and Wireless. The topics include: Demo: Do not trust your neighbors! a small iot platform illustrating a man-in-the-middle attack; a fuzzy based energy aware unequal clustering for wireless sensor networks; The trade-offs of cell over-provisioning in IEEE 802.15.4 TSCH networks; wireless network for in-car communication; Enhanced dynamic duty cycle in LoRaWAN network; Specificities of the LoRa™ physical layer for the development of new ad hoc MAC layers; A comparative evaluation of the performance of the multi-hop IoB-DTN routing protocol; Performance of selection combining macro diversity with outage probability constraint in LPWAN; Authenticated preambles for denial of service mitigation in LPWANs; Multi-path selection in RPL based on replication and elimination; communication architecture for unmanned aerial vehicle system; DACAR: Distributed & adaptable crosslayer anticollision and routing protocol for RFID; low frequency mobile communications in underwater networks; FPMIPV6-S: An enhanced mobility protocol for 6LoWPAN-based wireless mobile sensor networks; collaborative state estimation and actuator scheduling for cyber-physical systems under random multiple events; game-based data muling as a service in infrastructureless area; distributed computations in wireless sensor networks by local interactions; SPHERE deployment manager: A tool for deploying IoT sensor networks at large scale; constructing customized multi-hop topologies in dense wireless network testbeds; f-Interop platform and tools: Validating IoT implementations faster; performance evaluation of a rpl hybrid objective function for the smart grid network; latency and lifetime optimization for k-anycast routing algorithm in wireless sensor networks.
A32: R031 | B32: S1, S2 | C32: Secure Energy Constrained LoRa Mesh Network | D32: 2020 | E32: Conference paper | F32: Heeger, D.; Garigan, M.; Tsiropoulou, E.E.; Plusquellic, J. | G32: Lecture Notes in Computer Science (including subseries Lecture Notes in Artificial Intelligence and Lecture Notes in Bioinformatics) | H32: 10.1007/978-3-030-61746-2_17 | I32: Include | K32: 2.1 / 2.2 | L32: SEC | M32: High | O32: =IF(N32="",IF(I32="Include","Include",J32),N32) -> Include | P32: LoRa (Long Range) is a low-power wide-area network technology well-suited for Internet of Things (IoT) applications. In this paper, LoRa is used in a cattle monitoring application where an ad-hoc mesh network is configured to collect GPS and accelerometer data from cattle-worn sensors and relay the collected data to a base station. Free-range cattle monitoring is a challenging application since the battery-powered sensors must be small and energy efficient, and enable data communications over long distances from unpredictable locations. We propose novel changes to the existing LoRa mesh network protocols that minimize energy consumption by using global time synchronization enabled by GPS sensors and a concurrent transmission property unique to LoRa. The mesh routing phase efficiently occurs during every data collection period, making this approach ideal for networking highly mobile sensors. We integrate efficient authentication and encryption techniques in the data exchange operations to prevent spoofing and to provide confidentiality in the message exchanges between the sensors and the base station. The performance of the proposed secure implementation is compared to an equivalent insecure implementation. Multiple cattle distribution scenarios are constructed and compared to evaluate the energy consumption of the proposed scheme. © 2020, Springer Nature Switzerland AG.
